<!-- Define the robot model -->
<model name="robot_arm">
  <!-- Define the base link of the arm -->
  <link name="base_link">
    <!-- Define the pose of the base link with respect to the global frame -->
    <pose frame="" xyz="0 0 0" rpy="0 0 0" />
    ...
  </link>

  ...

</model>




<!-- Define the robot model -->
<model name="robot_arm">
  <!-- Define the base link of the arm -->
  <link name="base_link">
    ...
  </link>

  <!-- Define the first joint of the arm -->
  <joint name="joint1" type="revolute">
    <!-- Use D-H parameters to specify the joint's axis and limits -->
    <axis xyz="1 0 0" />
    <limit effort="..." velocity="..." lower="..." upper="..." />
    <!-- Connect the joint to the previous link -->
    <parent link="base_link" />
    <child link="link1" />
  </joint>

  <!-- Define the first link of the arm -->
  <link name="link1">
    ...
  </link>

  <!-- Define the second joint of the arm -->
  <joint name="joint2" type="revolute">
    <!-- Use D-H parameters to specify the joint's axis and limits -->
    <axis xyz="0 1 0" />
    <limit effort="..." velocity="..." lower="..." upper="..." />
    <!-- Connect the joint to the previous link -->
    <parent link="link1" />
    <child link="link2" />
  </joint>

  <!-- Define the second link of the arm -->
  <link name="link2">
    ...
  </link>

  <!-- Repeat the process for the remaining joints and links of the arm -->
  ...
</model>



<!-- Define the robot model -->
<model name="robot_arm">
  <!-- Define the base link of the arm -->
  <link name="base_link">
    ...
  </link>

  <!-- Define the first joint of the arm -->
  <joint name="joint1" type="revolute">
    <!-- Use D-H parameters to specify the joint's axis and limits -->
    <axis xyz="1 0 0" />
    <limit effort="..." velocity="..." lower="..." upper="..." />
    <!-- Add the D-H parameters -->
    <dh param="0 0.5 0 0" />
    <!-- Connect the joint to the previous link -->
    <parent link="base_link" />
    <child link="link1" />
  </joint>

  <!-- Define the first link of the arm -->
  <link name="link1">
    ...
  </link>

  <!-- Define the second joint of the arm -->
  <joint name="joint2" type="revolute">
    <!-- Use D-H parameters to specify the joint's axis and limits -->
    <axis xyz="0 1 0" />
    <limit effort="..." velocity="..." lower="..." upper="..." />
    <!-- Add the D-H parameters -->
    <dh param="0 0 0.5 0" />
    <!-- Connect the joint to the previous link -->
    <parent link="link1" />
    <child link="link2" />
  </joint>

  <!-- Define the second link of the arm -->
  <link name="link2">
    ...
  </link>

  <!-- Repeat the process for the remaining joints and links of the arm -->
  ...
</model>




<!-- Define the robot model -->
<model name="robot_arm">
  <!-- Define the base link of the arm -->
  <link name="base_link">
    ...
  </link>

  <!-- Use a for loop to define all of the joints and links of the arm -->
  <?for i in range(1, 7):?>
    <!-- Define the joint -->
    <joint name="joint<?=i?>" type="revolute">
      <!-- Use D-H parameters to specify the joint's axis and limits -->
      <axis xyz="1 0 0" />
      <limit effort="..." velocity="..." lower="..." upper="..." />
      <!-- Add the D-H parameters -->
      <dh param="0 0.5 0 0" />
      <!-- Connect the joint to the previous link -->
      <parent link="link<?=i-1?>" />
      <child link="link<?=i?>" />
    </joint>

    <!-- Define the link -->
    <link name="link<?=i?>">
      ...
    </link>
  <?endfor?>
</model>








<!-- Define the robot model -->
<model name="robot_arm">
  <!-- Define the base link of the arm -->
  <link name="base_link">
    ...
  </link>

  <!-- Define a 2D array of D-H parameters for each joint -->
  <?
    dh_params = [[0, 0.5, 0, 0],
                 [0, 0, 0.5, 0],
                 [0, 0, 0.5, 0],
                 [0, 0, 0.5, 0],
                 [0, 0, 0.5, 0],
                 [0, 0, 0.5, 0]]
  ?>

  <!-- Use a for loop to define all of the joints and links of the arm -->
  <?for i in range(1, 7):?>
    <!-- Define the joint -->
    <joint name="joint<?=i?>" type="revolute">
      <!-- Use D-H parameters to specify the joint's axis and limits -->
      <axis xyz="1 0 0" />
      <limit effort="..." velocity="..." lower="..." upper="..." />
      <!-- Add the D-H parameters from the array -->
      <dh param="<?=dh_params[i-1]?>" />
      <!-- Connect the joint to the previous link -->
      <parent link="link<?=i-1?>" />
      <child link="link<?=i?>" />
    </joint>

    <!-- Define the link -->
    <link name="link<?=i?>">
      ...
    </link>
  <?endfor?>
</model>
