<?xml version="1.0" ?>
<!-- =================================================================================== -->
<!-- |    This document was autogenerated by xacro from /examplerobot_workspace/src/examplerobot_description/urdf/examplerobot.xacro | -->
<!-- |    EDITING THIS FILE BY HAND IS NOT RECOMMENDED                                 | -->
<!-- =================================================================================== -->
<robot name="examplerobot">
    <gazebo>
        <plugin filename="libgazebo_ros_control.so" name="gazebo_ros_control">
            <robotNamespace>/examplerobot</robotNamespace>
        </plugin>
    </gazebo>
    <!-- END - Include -->
    <!-- BGN - Robot description -->
    <link name="ref_link">
        <collision>
            <origin rpy="0 0 0" xyz="0 0 0" />
            <geometry>
                <mesh filename="package://examplerobot_description/meshes/base_link.stl" scale="0.0001 0.0001 0.0001" />
            </geometry>
        </collision>
        <visual>
            <origin rpy="0 0 0" xyz="0 0 0" />
            <geometry>
                <mesh filename="package://examplerobot_description/meshes/base_link.stl" scale="0.0001 0.0001 0.0001" />
            </geometry>
            <material name="light_black" />
        </visual>
        
<inertial>
            <mass value="0.1" />
            <inertia ixx="0.03" iyy="0.03" izz="0.03" ixy="0.0" ixz="0.0" iyz="0.0" />
        </inertial>

    </link>
    <link name="base_link">
        
<inertial>
            <mass value="15.0" />
            <origin rpy="0 0 0" xyz="0 0 0" />
            <inertia ixx="5.3235" ixy="0" ixz="0" iyy="5.3235" iyz="0" izz="3.9655" />
        </inertial>

        <collision>
            <origin rpy="0 0 0" xyz="0 0 0" />
            <geometry>
                <mesh filename="package://examplerobot_description/meshes/base_link.stl" scale="0.001 0.001 0.001" />
            </geometry>
            <surface>
                <contact>
                    <collide_bitmask>0xFFFF</collide_bitmask>
                </contact>
                <friction>
                    <ode>
                        <mu>0.5</mu>
                        <mu2>0.5</mu2>
                    </ode>
                </friction>
            </surface>
        </collision>
        <visual>
            <origin rpy="0 0 0" xyz="0 0 0" />
            <geometry>
                <mesh filename="package://examplerobot_description/meshes/base_link.stl" scale="0.001 0.001 0.001" />
            </geometry>
            <material name="light_black" />
        </visual>
    </link>
    <link name="link_01">
        
<inertial>
            <mass value="2.0" />
            <origin rpy="0 0 0" xyz="0 0 0" />
            <inertia ixx="1.3235" ixy="0" ixz="0" iyy="1.3235" iyz="0" izz="0.9655" />
        </inertial>

        <collision>
            <origin rpy="0 0 0" xyz="0 0 0" />
            <geometry>
                <mesh filename="package://examplerobot_description/meshes/link1.stl" scale="0.001 0.001 0.001" />
            </geometry>
            <surface>
                <contact>
                    <collide_bitmask>0xFFFF</collide_bitmask>
                </contact>
                <friction>
                    <ode>
                        <mu>0.5</mu>
                        <mu2>0.5</mu2>
                    </ode>
                </friction>
            </surface>
        </collision>
        <visual>
            <origin rpy="0 0 0" xyz="0 0 0" />
            <geometry>
                <mesh filename="package://examplerobot_description/meshes/link1.stl" scale="0.001 0.001 0.001" />
            </geometry>
            <material name="light_black" />
        </visual>
    </link>
    <link name="link_02">
        
<inertial>
            <mass value="3.0" />
            <origin rpy="0 0 0" xyz="0 0 0" />
            <inertia ixx="1.3235" ixy="0" ixz="0" iyy="1.3235" iyz="0" izz="0.9655" />
        </inertial>

        <collision>
            <origin rpy="0 0 0" xyz="0 0 0" />
            <geometry>
                <mesh filename="package://examplerobot_description/meshes/link2.stl" scale="0.001 0.001 0.001" />
            </geometry>
            <surface>
                <contact>
                    <collide_bitmask>0xFFFF</collide_bitmask>
                </contact>
                <friction>
                    <ode>
                        <mu>0.5</mu>
                        <mu2>0.5</mu2>
                    </ode>
                </friction>
            </surface>
        </collision>
        <visual>
            <origin rpy="0 0 0" xyz="0 0 0" />
            <geometry>
                <mesh filename="package://examplerobot_description/meshes/link2.stl" scale="0.001 0.001 0.001" />
            </geometry>
            <material name="light_black" />
        </visual>
    </link>
    <link name="link_03">
        
<inertial>
            <mass value="2.0" />
            <origin rpy="0 0 0" xyz="0 0 0" />
            <inertia ixx="1.3235" ixy="0" ixz="0" iyy="1.3235" iyz="0" izz="0.9655" />
        </inertial>

        <collision>
            <origin rpy="0 0 0" xyz="0 0 0" />
            <geometry>
                <mesh filename="package://examplerobot_description/meshes/link3.stl" scale="0.001 0.001 0.001" />
            </geometry>
            <surface>
                <contact>
                    <collide_bitmask>0xFFFF</collide_bitmask>
                </contact>
                <friction>
                    <ode>
                        <mu>0.5</mu>
                        <mu2>0.5</mu2>
                    </ode>
                </friction>
            </surface>
        </collision>
        <visual>
            <origin rpy="0 0 0" xyz="0 0 0" />
            <geometry>
                <mesh filename="package://examplerobot_description/meshes/link3.stl" scale="0.001 0.001 0.001" />
            </geometry>
            <material name="light_black" />
        </visual>
    </link>
    <link name="link_04">
        
<inertial>
            <mass value="2.0" />
            <origin rpy="0 0 0" xyz="0 0 0" />
            <inertia ixx="1.3235" ixy="0" ixz="0" iyy="1.3235" iyz="0" izz="0.9655" />
        </inertial>

        <collision>
            <origin rpy="0 0 0" xyz="0 0 0" />
            <geometry>
                <mesh filename="package://examplerobot_description/meshes/link4.stl" scale="0.001 0.001 0.001" />
            </geometry>
            <surface>
                <contact>
                    <collide_bitmask>0xFFFF</collide_bitmask>
                </contact>
                <friction>
                    <ode>
                        <mu>0.5</mu>
                        <mu2>0.5</mu2>
                    </ode>
                </friction>
            </surface>
        </collision>
        <visual>
            <origin rpy="0 0 0" xyz="0 0 0" />
            <geometry>
                <mesh filename="package://examplerobot_description/meshes/link4.stl" scale="0.001 0.001 0.001" />
            </geometry>
            <material name="light_black" />
        </visual>
    </link>
    <link name="link_05">
        
<inertial>
            <mass value="2.0" />
            <origin rpy="0 0 0" xyz="0 0 0" />
            <inertia ixx="1.3235" ixy="0" ixz="0" iyy="1.3235" iyz="0" izz="0.9655" />
        </inertial>

        <collision>
            <origin rpy="0 0 0" xyz="0 0 0" />
            <geometry>
                <mesh filename="package://examplerobot_description/meshes/link5.stl" scale="0.001 0.001 0.001" />
            </geometry>
            <surface>
                <contact>
                    <collide_bitmask>0xFFFF</collide_bitmask>
                </contact>
                <friction>
                    <ode>
                        <mu>0.5</mu>
                        <mu2>0.5</mu2>
                    </ode>
                </friction>
            </surface>
        </collision>
        <visual>
            <origin rpy="0 0 0" xyz="0 0 0" />
            <geometry>
                <mesh filename="package://examplerobot_description/meshes/link5.stl" scale="0.001 0.001 0.001" />
            </geometry>
            <material name="light_black" />
        </visual>
    </link>
    <link name="end_effector">
        
<inertial>
            <mass value="1.0" />
            <origin rpy="0 0 0" xyz="0 0 0" />
            <inertia ixx="1.3235" ixy="0" ixz="0" iyy="1.3235" iyz="0" izz="0.9655" />
        </inertial>

        <collision>
            <origin rpy="0 0 0" xyz="0 0 0" />
            <geometry>
                <mesh filename="package://examplerobot_description/meshes/end_effector.stl" scale="0.001 0.001 0.001" />
            </geometry>
            <surface>
                <contact>
                    <collide_bitmask>0xFFFF</collide_bitmask>
                </contact>
                <friction>
                    <ode>
                        <mu>0.5</mu>
                        <mu2>0.5</mu2>
                    </ode>
                </friction>
            </surface>
        </collision>
        <visual>
            <origin rpy="0 0 0" xyz="0 0 0" />
            <geometry>
                <mesh filename="package://examplerobot_description/meshes/end_effector.stl" scale="0.001 0.001 0.001" />
            </geometry>
            <material name="light_black" />
        </visual>
    </link>
    <joint name="ref_link__base_link" type="fixed">
        <axis xyz="0 0 1" />
        <origin rpy="0 0 0" xyz="0 0 0" />
        <parent link="base_link" />
        <child link="ref_link" />
    </joint>
    <joint name="base_link__link_01" type="revolute">
        <axis xyz="0 0 1" />
        <limit effort="1000" lower="-3.14" upper="3.14" velocity="0.5" />
        <origin rpy="0 0 0" xyz="0 0 0.3" />
        <parent link="base_link" />
        <child link="link_01" />
    </joint>
    
<transmission name="trans_base_link__link_01">
        <type>transmission_interface/SimpleTransmission</type>
        <joint name="base_link__link_01">
            <hardwareInterface>hardware_interface/EffortJointInterface</hardwareInterface>
        </joint>
        <actuator name="motor_base_link__link_01">
            <hardwareInterface>hardware_interface/EffortJointInterface</hardwareInterface>
            <mechanicalReduction>1</mechanicalReduction>
        </actuator>
    </transmission>
    <joint name="link_01__link_02" type="revolute">
        <axis xyz="0 0 1" />
        <limit effort="1000" lower="-3.14" upper="3.14" velocity="0.5" />
        <origin rpy="-1.571 0 0" xyz="0 0 0.0" />
        <parent link="link_01" />
        <child link="link_02" />
    </joint>
    <transmission name="trans_link_01__link_02">
        <type>transmission_interface/SimpleTransmission</type>
        <joint name="link_01__link_02">
            <hardwareInterface>hardware_interface/EffortJointInterface</hardwareInterface>
        </joint>
        <actuator name="motor_link_01__link_02">
            <hardwareInterface>hardware_interface/EffortJointInterface</hardwareInterface>
            <mechanicalReduction>1</mechanicalReduction>
        </actuator>
    </transmission>
    <joint name="link_02__link_03" type="revolute">
        <axis xyz="0 0 1" />
        <limit effort="1000" lower="-3.14" upper="3.14" velocity="0.5" />
        <origin rpy="0 0 1.571" xyz="0.3 0 0.0" />
        <parent link="link_02" />
        <child link="link_03" />
    </joint>
    <transmission name="trans_link_02__link_03">
        <type>transmission_interface/SimpleTransmission</type>
        <joint name="link_02__link_03">
            <hardwareInterface>hardware_interface/EffortJointInterface</hardwareInterface>
        </joint>
        <actuator name="motor_link_02__link_03">
            <hardwareInterface>hardware_interface/EffortJointInterface</hardwareInterface>
            <mechanicalReduction>1</mechanicalReduction>
        </actuator>
    </transmission>
    <joint name="link_03__link_04" type="revolute">
        <axis xyz="0 0 1" />
        <limit effort="1000" lower="-3.14" upper="3.14" velocity="0.5" />
        <origin rpy="1.571 0 0" xyz="0 -0.300 0.0" />
        <parent link="link_03" />
        <child link="link_04" />
    </joint>
    <transmission name="trans_link_03__link_04">
        <type>transmission_interface/SimpleTransmission</type>
        <joint name="link_03__link_04">
            <hardwareInterface>hardware_interface/EffortJointInterface</hardwareInterface>
        </joint>
        <actuator name="motor_link_03__link_04">
            <hardwareInterface>hardware_interface/EffortJointInterface</hardwareInterface>
            <mechanicalReduction>1</mechanicalReduction>
        </actuator>
    </transmission>
    <joint name="link_04__link_05" type="revolute">
        <axis xyz="0 0 1" />
        <limit effort="1000" lower="-3.14" upper="3.14" velocity="0.5" />
        <origin rpy="-1.571 0 0" xyz="0 0 0.0" />
        <parent link="link_04" />
        <child link="link_05" />
    </joint>
    <transmission name="trans_link_04__link_05">
        <type>transmission_interface/SimpleTransmission</type>
        <joint name="link_04__link_05">
            <hardwareInterface>hardware_interface/EffortJointInterface</hardwareInterface>
        </joint>
        <actuator name="motor_link_04__link_05">
            <hardwareInterface>hardware_interface/EffortJointInterface</hardwareInterface>
            <mechanicalReduction>1</mechanicalReduction>
        </actuator>
    </transmission>
    <joint name="link_05__end_effector" type="revolute">
        <axis xyz="0 0 1" />
        <limit effort="1000" lower="-3.14" upper="3.14" velocity="0.5" />
        <origin rpy="1.571 0 0" xyz="0 -.200 0.0" />
        <parent link="link_05" />
        <child link="end_effector" />
    </joint>
    <transmission name="trans_link_05__end_effector">
        <type>transmission_interface/SimpleTransmission</type>
        <joint name="link_05__end_effector">
            <hardwareInterface>hardware_interface/EffortJointInterface</hardwareInterface>
        </joint>
        <actuator name="motor_link_05__end_effector">
            <hardwareInterface>hardware_interface/EffortJointInterface</hardwareInterface>
            <mechanicalReduction>1</mechanicalReduction>
        </actuator>
    </transmission>
    <!-- END - Robot description -->
    <gazebo>
        <plugin filename="libgazebo_ros_control.so" name="gazebo_ros_control" />
    </gazebo>
    <transmission name="trans_base_link__link_01">
        <type>transmission_interface/SimpleTransmission</type>
        <joint name="base_link__link_01">
            <hardwareInterface>hardware_interface/PositionJointInterface</hardwareInterface>
        </joint>
        <actuator name="base_link__link_01_motor">
            <hardwareInterface>hardware_interface/PositionJointInterface</hardwareInterface>
            <mechanicalReduction>1</mechanicalReduction>
        </actuator>
    </transmission>
    <transmission name="trans_link_01__link_02">
        <type>transmission_interface/SimpleTransmission</type>
        <joint name="link_01__link_02">
            <hardwareInterface>hardware_interface/PositionJointInterface</hardwareInterface>
        </joint>
        <actuator name="link_01__link_02_motor">
            <hardwareInterface>hardware_interface/PositionJointInterface</hardwareInterface>
            <mechanicalReduction>1</mechanicalReduction>
        </actuator>
    </transmission>
    <transmission name="trans_link_02__link_03">
        <type>transmission_interface/SimpleTransmission</type>
        <joint name="link_02__link_03">
            <hardwareInterface>hardware_interface/PositionJointInterface</hardwareInterface>
        </joint>
        <actuator name="link_02__link_03_motor">
            <hardwareInterface>hardware_interface/PositionJointInterface</hardwareInterface>
            <mechanicalReduction>1</mechanicalReduction>
        </actuator>
    </transmission>
    <transmission name="trans_link_03__link_04">
        <type>transmission_interface/SimpleTransmission</type>
        <joint name="link_03__link_04">
            <hardwareInterface>hardware_interface/PositionJointInterface</hardwareInterface>
        </joint>
        <actuator name="link_03__link_04_motor">
            <hardwareInterface>hardware_interface/PositionJointInterface</hardwareInterface>
            <mechanicalReduction>1</mechanicalReduction>
        </actuator>
    </transmission>
    <transmission name="trans_link_04__link_05">
        <type>transmission_interface/SimpleTransmission</type>
        <joint name="link_04__link_05">
            <hardwareInterface>hardware_interface/PositionJointInterface</hardwareInterface>
        </joint>
        <actuator name="link_04__link_05_motor">
            <hardwareInterface>hardware_interface/PositionJointInterface</hardwareInterface>
            <mechanicalReduction>1</mechanicalReduction>
        </actuator>
    </transmission>
    <transmission name="trans_link_05__end_effector">
        <type>transmission_interface/SimpleTransmission</type>
        <joint name="link_05__end_effector">
            <hardwareInterface>hardware_interface/PositionJointInterface</hardwareInterface>
        </joint>
        <actuator name="link_05__end_effector_motor">
            <hardwareInterface>hardware_interface/PositionJointInterface</hardwareInterface>
            <mechanicalReduction>1</mechanicalReduction>
        </actuator>
    </transmission>
    <gazebo>
        <plugin name="gazebo_ros_control" filename="libgazebo_ros_control.so">
            <robotNamespace>/</robotNamespace>
        </plugin>
    </gazebo>
</robot>