<!-- Define the robot model -->
<model name="examplerobot">
  <!-- Define the base link of the arm -->
  <link name="base_link">
    <!-- Define the visual and collision properties for the base link -->
    <visual>
      <!-- Use the <geometry> element to specify the 3D geometry of the link -->
      <geometry>
        <!-- Import the STL file for the link's geometry -->
        <mesh>
          <uri>model://examplerobot_description/meshes/base_link.stl</uri>
        </mesh>
      </geometry>
    </visual>
    <collision>
      <geometry>
        <mesh>
          <uri>model://examplerobot_description/meshes/base_link.stl</uri>
        </mesh>
      </geometry>
    </collision>
    ...
  </link>

  <!-- Define a 2D array of D-H parameters for each joint -->
  <?
    dh_params = [[0, 0.5, 0, 0],
                 [0, 0, 0.5, 0],
                 [0, 0, 0.5, 0],
                 [0, 0, 0.5, 0],
                 [0, 0, 0.5, 0],
                 [0, 0, 0.5, 0]]
  ?>

  <!-- Use a for loop to define all of the joints and links of the arm -->
  <?for i in range(1, 7):?>
    <!-- Define the joint -->
    <joint name="joint<?=i?>" type="revolute">
      <!-- Use D-H parameters to specify the joint's axis and limits -->
      <axis xyz="1 0 0" />
      <limit effort="..." velocity="..." lower="..." upper="..." />
      <!-- Add the D-H parameters from the array -->
      <dh param="<?=dh_params[i-1]?>" />
      <!-- Connect the joint to the previous link -->
      <parent link="link<?=i-1?>" />
      <child link="link<?=i?>" />
    </joint>

    <!-- Define the link -->
    <link name="link<?=i?>">
      ...
    </link>
  <?endfor?>
</model>






<robot name="robot">
  <link name="link1">
    <visual>
      <origin rpy="0 0 0" xyz="0 0 0"/>
      <geometry>
        <cylinder length="1" radius="0.1"/>
      </geometry>
    </visual>
    <collision>
      <origin rpy="0 0 0" xyz="0 0 0"/>
      <geometry>
        <cylinder length="1" radius="0.1"/>
      </geometry>
    </collision>
    <inertial>
      <mass value="1.0"/>
      <inertia ixx="1.0" ixy="0.0" ixz="0.0" iyy="1.0" iyz="0.0" izz="1.0"/>
    </inertial>
  </link>
  <link name="link2">
    <visual>
      <origin rpy="0 0 0" xyz="0 0 0"/>
      <geometry>
        <box size="1 1 1"/>
      </geometry>
    </visual>
    <collision>
      <origin rpy="0 0 0" xyz="0 0 0"/>
      <geometry>
        <box size="1 1 1"/>
      </geometry>
    </collision>
    <inertial>
      <mass value="1.0"/>
      <inertia ixx="1.0" ixy="0.0" ixz="0.0" iyy="1.0" iyz="0.0" izz="1.0"/>
    </inertial>
  </link>
  <joint name="joint1" type="revolute">
    <origin rpy="0 0 0" xyz="0 0 0"/>
    <parent link="link1"/>
    <child link="link2"/>
    <axis xyz="1 0 0"/>
    <dynamics damping="0.1" friction="0.1"/>
    <limit effort="100" lower="-3.14" upper="3.14" velocity="1"/>
    <safety_controller k_velocity="1.0" soft_lower_limit="-3.14" soft_upper_limit="3.14"/>
    <kinematic>
      <limits effort="100" lower="-3.14" upper="3.14" velocity="1"/>
      <dynamics damping="0.1" friction="0.1"/>
    </kinematic>
    <dh param="0.0" a="0.0" alpha="0.0" d="0.0" theta="0.0"/>
  </joint>
</robot>
